<?xml version="1.0" ?>
<!-- =================================================================================== -->
<!-- |    This document was autogenerated by xacro from assembly.urdf.xacro            | -->
<!-- |    EDITING THIS FILE BY HAND IS NOT RECOMMENDED                                 | -->
<!-- =================================================================================== -->
<robot name="assembly">
  <link name="sensor_shovel">
    <visual>
      <origin rpy="0 0 0" xyz="0 0 0"/>
      <geometry>
        <mesh filename="meshes/base_link.STL"/>
      </geometry>
      <material name="mat_sensor_shovel">
        <color rgba="0.79216078 0.81961176 0.92941569 1.00000000"/>
      </material>
    </visual>
    <collision>
      <origin rpy="0 0 0" xyz="0 0 0"/>
      <geometry>
        <mesh filename="meshes/base_link.STL"/>
      </geometry>
    </collision>
    <inertial>
      <origin rpy="0 0 0" xyz="-0.11585 0.0005511 0.051294"/>
      <mass value="2.3"/>
      <inertia ixx="0.0005331" ixy="0.0002664" ixz="0.0000158" iyy="0.0080026" iyz="0" izz="0.0082034"/>
    </inertial>
  </link>
  <link name="sensor_shovel_tcp">
    <visual>
      <origin rpy="0 0 0" xyz="0 0 0"/>
      <geometry>
        <mesh filename="meshes/shovel_tcp.STL"/>
      </geometry>
      <material name="mat_shovel_tcp">
        <color rgba="1.00000000 1.00000000 1.00000000 1.00000000"/>
      </material>
    </visual>
    <collision>
      <origin rpy="0 0 0" xyz="0 0 0"/>
      <geometry>
        <mesh filename="meshes/shovel_tcp.STL"/>
      </geometry>
    </collision>
    <inertial>
      <origin rpy="0 0 0" xyz="0 -0.0002919 -0.00005"/>
      <mass value="0"/>
      <inertia ixx="0" ixy="0" ixz="0" iyy="0" iyz="0" izz="0"/>
    </inertial>
  </link>
  <link name="ur10">
    <visual>
      <origin rpy="0 0 0" xyz="0 0 0"/>
      <geometry>
        <mesh filename="meshes/base.dae"/>
      </geometry>
      <material name="SWMaterial-2_001">
        <color rgba="0.37255294 0.37255294 0.37255294 1.00000000"/>
      </material>
    </visual>
    <collision>
      <origin rpy="0 0 0" xyz="0 0 0.019"/>
      <geometry>
        <cylinder length="0.038" radius="0.075"/>
      </geometry>
    </collision>
    <inertial>
      <origin rpy="0 0 0" xyz="0 0 0"/>
      <mass value="4"/>
      <inertia ixx="0.0061063" ixy="0" ixz="0" iyy="0.0061063" iyz="0" izz="0.01125"/>
    </inertial>
  </link>
  <link name="ur10_shoulder">
    <visual>
      <origin rpy="0 0 0" xyz="0 0 0"/>
      <geometry>
        <mesh filename="meshes/shoulder.dae"/>
      </geometry>
      <material name="SWMaterial-0">
        <color rgba="0.22353333 0.22353333 0.22353333 1.00000000"/>
      </material>
      <material name="SWMaterial-1">
        <color rgba="0.39216078 0.54118039 0.63921961 1.00000000"/>
      </material>
      <material name="SWMaterial-2">
        <color rgba="0.46274902 0.46274902 0.46274902 1.00000000"/>
      </material>
    </visual>
    <collision>
      <origin rpy="0 0 0" xyz="0 0 0"/>
      <geometry>
        <cylinder length="0.177" radius="0.075"/>
      </geometry>
    </collision>
    <inertial>
      <origin rpy="0 0 0" xyz="0 0 0"/>
      <mass value="7.778"/>
      <inertia ixx="0.0314743" ixy="0" ixz="0" iyy="0.0314743" iyz="0" izz="0.0218756"/>
    </inertial>
  </link>
  <link name="ur10_upper_arm">
    <visual>
      <origin rpy="0 0 0" xyz="0 0 0"/>
      <geometry>
        <mesh filename="meshes/upperarm.dae"/>
      </geometry>
      <material name="SWMaterial-0">
        <color rgba="0.22353333 0.22353333 0.22353333 1.00000000"/>
      </material>
      <material name="SWMaterial-1">
        <color rgba="0.39216078 0.54118039 0.63921961 1.00000000"/>
      </material>
      <material name="SWMaterial-2">
        <color rgba="0.46274902 0.46274902 0.46274902 1.00000000"/>
      </material>
      <material name="SWMaterial-3">
        <color rgba="0.65490588 0.65490588 0.65490588 1.00000000"/>
      </material>
    </visual>
    <collision>
      <origin rpy="1.5707 0 0" xyz="0 -0.045 0"/>
      <geometry>
        <cylinder length="0.177" radius="0.075"/>
      </geometry>
    </collision>
    <collision>
      <origin rpy="0 0 1.5707" xyz="0 -0.0436 0.32"/>
      <geometry>
        <cylinder length="0.461" radius="0.058"/>
      </geometry>
    </collision>
    <collision>
      <origin rpy="1.5707 0 0" xyz="0 -0.04 0.613"/>
      <geometry>
        <cylinder length="0.129" radius="0.058"/>
      </geometry>
    </collision>
    <inertial>
      <origin rpy="0 0 0" xyz="0 0 0.306"/>
      <mass value="12.93"/>
      <inertia ixx="0.421754" ixy="0" ixz="0" iyy="0.421754" iyz="0" izz="0.0363656"/>
    </inertial>
  </link>
  <link name="ur10_forearm">
    <visual>
      <origin rpy="0 0 0" xyz="0 0 0"/>
      <geometry>
        <mesh filename="meshes/forearm.dae"/>
      </geometry>
      <material name="SWMaterial-0">
        <color rgba="0.22353333 0.22353333 0.22353333 1.00000000"/>
      </material>
      <material name="SWMaterial-1">
        <color rgba="0.39216078 0.54118039 0.63921961 1.00000000"/>
      </material>
      <material name="SWMaterial-2">
        <color rgba="0.46274902 0.46274902 0.46274902 1.00000000"/>
      </material>
      <material name="SWMaterial-3">
        <color rgba="0.65490588 0.65490588 0.65490588 1.00000000"/>
      </material>
      <material name="SWMaterial-4">
        <color rgba="0.07843529 0.07843529 0.07843529 1.00000000"/>
      </material>
    </visual>
    <collision>
      <origin rpy="1.5707 0 0" xyz="0 0 0.001"/>
      <geometry>
        <cylinder length="0.136" radius="0.058"/>
      </geometry>
    </collision>
    <collision>
      <origin rpy="0 0 1.5707" xyz="0 0 0.305"/>
      <geometry>
        <cylinder length="0.447" radius="0.045"/>
      </geometry>
    </collision>
    <collision>
      <origin rpy="1.5707 0 0" xyz="0 0.001 0.5735"/>
      <geometry>
        <cylinder length="0.119" radius="0.045"/>
      </geometry>
    </collision>
    <inertial>
      <origin rpy="0 0 0" xyz="0 0 0.28615"/>
      <mass value="3.87"/>
      <inertia ixx="0.11107" ixy="0" ixz="0" iyy="0.11107" iyz="0" izz="0.0108844"/>
    </inertial>
  </link>
  <link name="ur10_wrist_1">
    <visual>
      <origin rpy="0 0 0" xyz="0 0 0"/>
      <geometry>
        <mesh filename="meshes/wrist1.dae"/>
      </geometry>
      <material name="SWMaterial-0_001">
        <color rgba="0.22353333 0.22353333 0.22353333 1.00000000"/>
      </material>
      <material name="SWMaterial-1_001">
        <color rgba="0.39216078 0.54118039 0.63921961 1.00000000"/>
      </material>
      <material name="SWMaterial-2_001">
        <color rgba="0.46274902 0.46274902 0.46274902 1.00000000"/>
      </material>
    </visual>
    <collision>
      <origin rpy="0 0 0" xyz="0 0.115 0.0025"/>
      <geometry>
        <cylinder length="0.119" radius="0.0455"/>
      </geometry>
    </collision>
    <inertial>
      <origin rpy="0 0 0" xyz="0 0 0"/>
      <mass value="1.96"/>
      <inertia ixx="0.0051082" ixy="0" ixz="0" iyy="0.0051082" iyz="0" izz="0.0055125"/>
    </inertial>
  </link>
  <link name="ur10_wrist_2">
    <visual>
      <origin rpy="0 0 0" xyz="0 0 0"/>
      <geometry>
        <mesh filename="meshes/wrist2.dae"/>
      </geometry>
      <material name="SWMaterial-0_002">
        <color rgba="0.22353333 0.22353333 0.22353333 1.00000000"/>
      </material>
      <material name="SWMaterial-1_002">
        <color rgba="0.39216078 0.54118039 0.63921961 1.00000000"/>
      </material>
      <material name="SWMaterial-2_002">
        <color rgba="0.46274902 0.46274902 0.46274902 1.00000000"/>
      </material>
    </visual>
    <collision>
      <origin rpy="1.5707 0 0" xyz="0 0.002 0.11659"/>
      <geometry>
        <cylinder length="0.119" radius="0.0455"/>
      </geometry>
    </collision>
    <inertial>
      <origin rpy="0 0 0" xyz="0 0 0"/>
      <mass value="1.96"/>
      <inertia ixx="0.0051082" ixy="0" ixz="0" iyy="0.0051082" iyz="0" izz="0.0055125"/>
    </inertial>
  </link>
  <link name="ur10_wrist_3">
    <visual>
      <origin rpy="0 0 0" xyz="0 0 0"/>
      <geometry>
        <mesh filename="meshes/wrist3.dae"/>
      </geometry>
      <material name="SWMaterial-2_003">
        <color rgba="0.46274902 0.46274902 0.46274902 1.00000000"/>
      </material>
    </visual>
    <collision>
      <origin rpy="1.5707 0 0" xyz="0 0.0765 0"/>
      <geometry>
        <cylinder length="0.031" radius="0.045"/>
      </geometry>
    </collision>
    <inertial>
      <origin rpy="0 0 0" xyz="0 0 0"/>
      <mass value="0.202"/>
      <inertia ixx="0.0005265" ixy="0" ixz="0" iyy="0.0005265" iyz="0" izz="0.0005681"/>
    </inertial>
  </link>
  <link name="base_jizuo">
    <visual>
      <origin rpy="0 0 0" xyz="0 0 0"/>
      <geometry>
        <mesh filename="meshes/base_link_world_jizuo.STL"/>
      </geometry>
      <material name="mat_base_jizuo">
        <color rgba="1.00000000 1.00000000 1.00000000 1.00000000"/>
      </material>
    </visual>
    <collision>
      <origin rpy="0 0 0" xyz="0 0 0"/>
      <geometry>
        <mesh filename="meshes/base_link_world_jizuo.STL"/>
      </geometry>
    </collision>
    <inertial>
      <origin rpy="0 0 0" xyz="-1.8696 -0.046752 0.24794"/>
      <mass value="1499.1"/>
      <inertia ixx="1126.8" ixy="-0.036857" ixz="0.0017432" iyy="2608.5" iyz="-18.236" izz="3614.6"/>
    </inertial>
  </link>
  <link name="base_jizuo_base_ur10_with_dizuo">
    <visual>
      <origin rpy="0 0 0" xyz="0 0 0"/>
      <geometry>
        <mesh filename="meshes/base_ur10_with_dizuo.STL"/>
      </geometry>
      <material name="mat_base_ur10_with_dizuo">
        <color rgba="1.00000000 1.00000000 1.00000000 1.00000000"/>
      </material>
    </visual>
    <collision>
      <origin rpy="0 0 0" xyz="0 0 0"/>
      <geometry>
        <mesh filename="meshes/base_ur10_with_dizuo.STL"/>
      </geometry>
    </collision>
    <inertial>
      <origin rpy="0 0 0" xyz="0 0 0.005"/>
      <mass value="0.225"/>
      <inertia ixx="0.0004237" ixy="0" ixz="0" iyy="0.0004237" iyz="0" izz="0.0008437"/>
    </inertial>
  </link>
  <joint name="sensor_shovel_tcp_fixed" type="fixed">
    <parent link="sensor_shovel"/>
    <child link="sensor_shovel_tcp"/>
    <origin rpy="-1.5708 1.5708 -0.61087" xyz="-0.47377 0.077109 0.0733"/>
  </joint>
  <joint name="ur10_shoulder_pan" type="revolute">
    <parent link="ur10"/>
    <child link="ur10_shoulder"/>
    <origin rpy="0 0 0" xyz="0 0 0.1273"/>
    <axis xyz="0 0 1"/>
    <limit effort="330" lower="-6.28319" upper="6.28319" velocity="2.16"/>
  </joint>
  <joint name="ur10_shoulder_lift" type="revolute">
    <parent link="ur10_shoulder"/>
    <child link="ur10_upper_arm"/>
    <origin rpy="0 1.57079 0" xyz="0 0.220941 0"/>
    <axis xyz="0 1 0"/>
    <limit effort="330" lower="-6.28319" upper="6.28319" velocity="2.16"/>
  </joint>
  <joint name="ur10_elbow" type="revolute">
    <parent link="ur10_upper_arm"/>
    <child link="ur10_forearm"/>
    <origin rpy="0 0 0" xyz="-0.0000039 -0.1719 0.612"/>
    <axis xyz="0 1 0"/>
    <limit effort="150" lower="-6.28319" upper="6.28319" velocity="3.15"/>
  </joint>
  <joint name="ur10_wrist_1" type="revolute">
    <parent link="ur10_forearm"/>
    <child link="ur10_wrist_1"/>
    <origin rpy="0 1.5707895 0.0000027" xyz="-0.0000036 0 0.5723"/>
    <axis xyz="0 1 0"/>
    <limit effort="54" lower="-6.28319" upper="6.28319" velocity="3.2"/>
  </joint>
  <joint name="ur10_wrist_2" type="revolute">
    <parent link="ur10_wrist_1"/>
    <child link="ur10_wrist_2"/>
    <origin rpy="0 0 0" xyz="0.0000003 0.1149 0.0000003"/>
    <axis xyz="0 0 -1"/>
    <limit effort="54" lower="-6.28319" upper="6.28319" velocity="3.2"/>
  </joint>
  <joint name="ur10_wrist_3" type="revolute">
    <parent link="ur10_wrist_2"/>
    <child link="ur10_wrist_3"/>
    <origin rpy="0 0 0" xyz="0 -0.0000003 0.1157"/>
    <axis xyz="0 1 0"/>
    <limit effort="54" lower="-6.28319" upper="6.28319" velocity="3.2"/>
  </joint>
  <joint name="base_jizuo_square_place" type="fixed">
    <parent link="base_jizuo"/>
    <child link="base_jizuo_base_ur10_with_dizuo"/>
    <origin rpy="3.1416 0 -1.5708" xyz="-0.78172 -0.025653 1.1638"/>
  </joint>
  <joint name="ur10-sensor_shovel" type="fixed">
    <parent link="ur10_wrist_3"/>
    <child link="sensor_shovel"/>
    <origin rpy="-1.5707963 0 0" xyz="0 0.09 0"/>
  </joint>
  <joint name="base_jizuo-ur10" type="fixed">
    <parent link="base_jizuo_base_ur10_with_dizuo"/>
    <child link="ur10"/>
    <origin rpy=" 0 0 0" xyz="0 0 0"/>
  </joint>
</robot>
