<?xml version="1.0"?>
<robot name="assembly" xmlns:xacro="http://www.ros.org/wiki/xacro">
  <xacro:arg name="mesh_root" default="$(find assembly_description)/urdf/meshes" />
  <xacro:arg name="hardware_backend" default="gazebo" />

  <link name="sensor_shovel">
    <visual>
      <origin xyz="0 0 0" rpy="0 0 0" />
      <geometry>
        <mesh filename="file://$(arg mesh_root)/base_link.STL" />
      </geometry>
      <material name="mat_sensor_shovel">
        <color rgba="0.79216078 0.81961176 0.92941569 1.00000000"/>
      </material>
    </visual>
    <collision>
      <origin xyz="0 0 0" rpy="0 0 0" />
      <geometry>
        <mesh filename="file://$(arg mesh_root)/base_link.STL" />
      </geometry>
    </collision>
    <inertial>
      <origin xyz="-0.11585 0.0005511 0.051294" rpy="0 0 0" />
      <mass value="2.3" />
      <inertia ixx="0.0005331" ixy="0.0002664" ixz="0.0000158" iyy="0.0080026" iyz="0" izz="0.0082034" />
    </inertial>
  </link>

  <link name="sensor_shovel_shovel_tcp">
    <visual>
      <origin xyz="0 0 0" rpy="0 0 0" />
      <geometry>
        <mesh filename="file://$(arg mesh_root)/shovel_tcp.STL" />
      </geometry>
      <material name="mat_shovel_tcp">
        <color rgba="1.00000000 1.00000000 1.00000000 1.00000000"/>
      </material>
    </visual>
    <collision>
      <origin xyz="0 0 0" rpy="0 0 0" />
      <geometry>
        <mesh filename="file://$(arg mesh_root)/shovel_tcp.STL" />
      </geometry>
    </collision>
    <inertial>
      <origin xyz="0 -0.0002919 -0.00005" rpy="0 0 0" />
      <mass value="0" />
      <inertia ixx="0" ixy="0" ixz="0" iyy="0" iyz="0" izz="0" />
    </inertial>
  </link>

  <link name="ur10">
    <visual>
      <origin xyz="0 0 0" rpy="0 0 0" />
      <geometry>
        <mesh filename="file://$(arg mesh_root)/base.dae" />
      </geometry>
      <material name="SWMaterial-2_001">
        <color rgba="0.37255294 0.37255294 0.37255294 1.00000000"/>
      </material>
    </visual>
    <collision>
      <origin xyz="0 0 0.019" rpy="0 0 0" />
      <geometry>
        <cylinder radius="0.075" length="0.038" />
      </geometry>
    </collision>
    <inertial>
      <origin xyz="0 0 0" rpy="0 0 0" />
      <mass value="4" />
      <inertia ixx="0.0061063" ixy="0" ixz="0" iyy="0.0061063" iyz="0" izz="0.01125" />
    </inertial>
  </link>

  <link name="ur10_shoulder">
    <visual>
      <origin xyz="0 0 0" rpy="0 0 0" />
      <geometry>
        <mesh filename="file://$(arg mesh_root)/shoulder.dae" />
      </geometry>
      <material name="SWMaterial-0">
        <color rgba="0.22353333 0.22353333 0.22353333 1.00000000"/>
      </material>
      <material name="SWMaterial-1">
        <color rgba="0.39216078 0.54118039 0.63921961 1.00000000"/>
      </material>
      <material name="SWMaterial-2">
        <color rgba="0.46274902 0.46274902 0.46274902 1.00000000"/>
      </material>
    </visual>
    <collision>
      <origin xyz="0 0 0" rpy="0 0 0" />
      <geometry>
        <cylinder radius="0.075" length="0.177" />
      </geometry>
    </collision>
    <inertial>
      <origin xyz="0 0 0" rpy="0 0 0" />
      <mass value="7.778" />
      <inertia ixx="0.0314743" ixy="0" ixz="0" iyy="0.0314743" iyz="0" izz="0.0218756" />
    </inertial>
  </link>

  <link name="ur10_upper_arm">
    <visual>
      <origin xyz="0 0 0" rpy="0 0 0" />
      <geometry>
        <mesh filename="file://$(arg mesh_root)/upperarm.dae" />
      </geometry>
      <material name="SWMaterial-0">
        <color rgba="0.22353333 0.22353333 0.22353333 1.00000000"/>
      </material>
      <material name="SWMaterial-1">
        <color rgba="0.39216078 0.54118039 0.63921961 1.00000000"/>
      </material>
      <material name="SWMaterial-2">
        <color rgba="0.46274902 0.46274902 0.46274902 1.00000000"/>
      </material>
      <material name="SWMaterial-3">
        <color rgba="0.65490588 0.65490588 0.65490588 1.00000000"/>
      </material>
    </visual>
    <collision>
      <origin xyz="0 -0.045 0" rpy="1.5707 0 0" />
      <geometry>
        <cylinder radius="0.075" length="0.177" />
      </geometry>
    </collision>
    <collision>
      <origin xyz="0 -0.0436 0.32" rpy="0 0 1.5707" />
      <geometry>
        <cylinder radius="0.058" length="0.461" />
      </geometry>
    </collision>
    <collision>
      <origin xyz="0 -0.04 0.613" rpy="1.5707 0 0" />
      <geometry>
        <cylinder radius="0.058" length="0.129" />
      </geometry>
    </collision>
    <inertial>
      <origin xyz="0 0 0.306" rpy="0 0 0" />
      <mass value="12.93" />
      <inertia ixx="0.421754" ixy="0" ixz="0" iyy="0.421754" iyz="0" izz="0.0363656" />
    </inertial>
  </link>

  <link name="ur10_forearm">
    <visual>
      <origin xyz="0 0 0" rpy="0 0 0" />
      <geometry>
        <mesh filename="file://$(arg mesh_root)/forearm.dae" />
      </geometry>
      <material name="SWMaterial-0">
        <color rgba="0.22353333 0.22353333 0.22353333 1.00000000"/>
      </material>
      <material name="SWMaterial-1">
        <color rgba="0.39216078 0.54118039 0.63921961 1.00000000"/>
      </material>
      <material name="SWMaterial-2">
        <color rgba="0.46274902 0.46274902 0.46274902 1.00000000"/>
      </material>
      <material name="SWMaterial-3">
        <color rgba="0.65490588 0.65490588 0.65490588 1.00000000"/>
      </material>
      <material name="SWMaterial-4">
        <color rgba="0.07843529 0.07843529 0.07843529 1.00000000"/>
      </material>
    </visual>
    <collision>
      <origin xyz="0 0 0.001" rpy="1.5707 0 0" />
      <geometry>
        <cylinder radius="0.058" length="0.136" />
      </geometry>
    </collision>
    <collision>
      <origin xyz="0 0 0.305" rpy="0 0 1.5707" />
      <geometry>
        <cylinder radius="0.045" length="0.447" />
      </geometry>
    </collision>
    <collision>
      <origin xyz="0 0.001 0.5735" rpy="1.5707 0 0" />
      <geometry>
        <cylinder radius="0.045" length="0.119" />
      </geometry>
    </collision>
    <inertial>
      <origin xyz="0 0 0.28615" rpy="0 0 0" />
      <mass value="3.87" />
      <inertia ixx="0.11107" ixy="0" ixz="0" iyy="0.11107" iyz="0" izz="0.0108844" />
    </inertial>
  </link>

  <link name="ur10_wrist_1_link">
    <visual>
      <origin xyz="0 0 0" rpy="0 0 0" />
      <geometry>
        <mesh filename="file://$(arg mesh_root)/wrist1.dae" />
      </geometry>
      <material name="SWMaterial-0_001">
        <color rgba="0.22353333 0.22353333 0.22353333 1.00000000"/>
      </material>
      <material name="SWMaterial-1_001">
        <color rgba="0.39216078 0.54118039 0.63921961 1.00000000"/>
      </material>
      <material name="SWMaterial-2_001">
        <color rgba="0.46274902 0.46274902 0.46274902 1.00000000"/>
      </material>
    </visual>
    <collision>
      <origin xyz="0 0.115 0.0025" rpy="0 0 0" />
      <geometry>
        <cylinder radius="0.0455" length="0.119" />
      </geometry>
    </collision>
    <inertial>
      <origin xyz="0 0 0" rpy="0 0 0" />
      <mass value="1.96" />
      <inertia ixx="0.0051082" ixy="0" ixz="0" iyy="0.0051082" iyz="0" izz="0.0055125" />
    </inertial>
  </link>

  <link name="ur10_wrist_2_link">
    <visual>
      <origin xyz="0 0 0" rpy="0 0 0" />
      <geometry>
        <mesh filename="file://$(arg mesh_root)/wrist2.dae" />
      </geometry>
      <material name="SWMaterial-0_002">
        <color rgba="0.22353333 0.22353333 0.22353333 1.00000000"/>
      </material>
      <material name="SWMaterial-1_002">
        <color rgba="0.39216078 0.54118039 0.63921961 1.00000000"/>
      </material>
      <material name="SWMaterial-2_002">
        <color rgba="0.46274902 0.46274902 0.46274902 1.00000000"/>
      </material>
    </visual>
    <collision>
      <origin xyz="0 0.002 0.11659" rpy="1.5707 0 0" />
      <geometry>
        <cylinder radius="0.0455" length="0.119" />
      </geometry>
    </collision>
    <inertial>
      <origin xyz="0 0 0" rpy="0 0 0" />
      <mass value="1.96" />
      <inertia ixx="0.0051082" ixy="0" ixz="0" iyy="0.0051082" iyz="0" izz="0.0055125" />
    </inertial>
  </link>

  <link name="ur10_wrist_3_link">
    <visual>
      <origin xyz="0 0 0" rpy="0 0 0" />
      <geometry>
        <mesh filename="file://$(arg mesh_root)/wrist3.dae" />
      </geometry>
      <material name="SWMaterial-2_003">
        <color rgba="0.46274902 0.46274902 0.46274902 1.00000000"/>
      </material>
    </visual>
    <collision>
      <origin xyz="0 0.0765 0" rpy="1.5707 0 0" />
      <geometry>
        <cylinder radius="0.045" length="0.031" />
      </geometry>
    </collision>
    <inertial>
      <origin xyz="0 0 0" rpy="0 0 0" />
      <mass value="0.202" />
      <inertia ixx="0.0005265" ixy="0" ixz="0" iyy="0.0005265" iyz="0" izz="0.0005681" />
    </inertial>
  </link>

  <link name="base_jizuo">
    <visual>
      <origin xyz="0 0 0" rpy="0 0 0" />
      <geometry>
        <mesh filename="file://$(arg mesh_root)/base_link_world_jizuo.STL" />
      </geometry>
      <material name="mat_base_jizuo">
        <color rgba="1.00000000 1.00000000 1.00000000 1.00000000"/>
      </material>
    </visual>
    <collision>
      <origin xyz="0 0 0" rpy="0 0 0" />
      <geometry>
        <mesh filename="file://$(arg mesh_root)/base_link_world_jizuo.STL" />
      </geometry>
    </collision>
    <inertial>
      <origin xyz="-1.8696 -0.046752 0.24794" rpy="0 0 0" />
      <mass value="1499.1" />
      <inertia ixx="1126.8" ixy="-0.036857" ixz="0.0017432" iyy="2608.5" iyz="-18.236" izz="3614.6" />
    </inertial>
  </link>

  <link name="base_jizuo_base_ur10_with_dizuo">
    <visual>
      <origin xyz="0 0 0" rpy="0 0 0" />
      <geometry>
        <mesh filename="file://$(arg mesh_root)/base_ur10_with_dizuo.STL" />
      </geometry>
      <material name="mat_base_ur10_with_dizuo">
        <color rgba="1.00000000 1.00000000 1.00000000 1.00000000"/>
      </material>
    </visual>
    <collision>
      <origin xyz="0 0 0" rpy="0 0 0" />
      <geometry>
        <mesh filename="file://$(arg mesh_root)/base_ur10_with_dizuo.STL" />
      </geometry>
    </collision>
    <inertial>
      <origin xyz="0 0 0.005" rpy="0 0 0" />
      <mass value="0.225" />
      <inertia ixx="0.0004237" ixy="0" ixz="0" iyy="0.0004237" iyz="0" izz="0.0008437" />
    </inertial>
  </link>

  <joint name="sensor_shovel_tcp" type="fixed">
    <parent link="sensor_shovel" />
    <child link="sensor_shovel_shovel_tcp" />
    <origin xyz="-0.47377 0.077109 0.0733" rpy="-1.5708 1.5708 -0.61087" />
  </joint>

  <joint name="ur10_shoulder_pan" type="revolute">
    <parent link="ur10" />
    <child link="ur10_shoulder" />
    <origin xyz="0 0 0.1273" rpy="0 0 0" />
    <axis xyz="0 0 1" />
    <limit lower="-6.28319" upper="6.28319" effort="330" velocity="2.16" />
  </joint>

  <joint name="ur10_shoulder_lift" type="revolute">
    <parent link="ur10_shoulder" />
    <child link="ur10_upper_arm" />
    <origin xyz="0 0.220941 0" rpy="0 1.57079 0" />
    <axis xyz="0 1 0" />
    <limit lower="-6.28319" upper="6.28319" effort="330" velocity="2.16" />
  </joint>

  <joint name="ur10_elbow" type="revolute">
    <parent link="ur10_upper_arm" />
    <child link="ur10_forearm" />
    <origin xyz="-0.0000039 -0.1719 0.612" rpy="0 0 0" />
    <axis xyz="0 1 0" />
    <limit lower="-6.28319" upper="6.28319" effort="150" velocity="3.15" />
  </joint>

  <joint name="ur10_wrist_1" type="revolute">
    <parent link="ur10_forearm" />
    <child link="ur10_wrist_1_link" />
    <origin xyz="-0.0000036 0 0.5723" rpy="0 1.5707895 0.0000027" />
    <axis xyz="0 1 0" />
    <limit lower="-6.28319" upper="6.28319" effort="54" velocity="3.2" />
  </joint>

  <joint name="ur10_wrist_2" type="revolute">
    <parent link="ur10_wrist_1_link" />
    <child link="ur10_wrist_2_link" />
    <origin xyz="0.0000003 0.1149 0.0000003" rpy="0 0 0" />
    <axis xyz="0 0 -1" />
    <limit lower="-6.28319" upper="6.28319" effort="54" velocity="3.2" />
  </joint>

  <joint name="ur10_wrist_3" type="revolute">
    <parent link="ur10_wrist_2_link" />
    <child link="ur10_wrist_3_link" />
    <origin xyz="0 -0.0000003 0.1157" rpy="0 0 0" />
    <axis xyz="0 1 0" />
    <limit lower="-6.28319" upper="6.28319" effort="54" velocity="3.2" />
  </joint>

  <joint name="base_jizuo_square_place" type="fixed">
    <parent link="base_jizuo" />
    <child link="base_jizuo_base_ur10_with_dizuo" />
    <origin xyz="-0.78172 -0.025653 1.1638" rpy="3.1416 0 -1.5708" />
  </joint>

  <joint name="ur10-sensor_shovel" type="fixed">
    <parent link="ur10_wrist_3_link" />
    <child link="sensor_shovel" />
    <origin xyz="0 0.09 0" rpy="0 1.5707963 1.5707963" quat_xyzw="-0.5 -0.5 -0.5 0.5" />
  </joint>

  <joint name="base_jizuo-ur10" type="fixed">
    <parent link="base_jizuo_base_ur10_with_dizuo" />
    <child link="ur10" />
    <origin xyz="0 0 0" rpy=" 0 0 0" quat_xyzw="0 0 0.70710678 0.70710678" />
  </joint>


  <xacro:arg name="ros_profile" default="ros2" />
  <xacro:arg name="ros_hardware_interface" default="position" />
  <xacro:property name="hardware_backend_arg" value="$(arg hardware_backend)" />
  <xacro:property name="ros_profile_arg" value="$(arg ros_profile)" />
  <xacro:property name="ros_hardware_interface_arg" value="$(arg ros_hardware_interface)" />

  <xacro:if value="${ros_profile_arg == 'ros1' and ros_hardware_interface_arg == 'effort'}">
      <transmission name="ur10_shoulder_pan_trans">
        <type>transmission_interface/SimpleTransmission</type>
        <joint name="ur10_shoulder_pan">
          <hardwareInterface>hardware_interface/EffortJointInterface</hardwareInterface>
        </joint>
        <actuator name="ur10_shoulder_pan_motor">
          <hardwareInterface>hardware_interface/EffortJointInterface</hardwareInterface>
          <mechanicalReduction>1</mechanicalReduction>
        </actuator>
      </transmission>

      <transmission name="ur10_shoulder_lift_trans">
        <type>transmission_interface/SimpleTransmission</type>
        <joint name="ur10_shoulder_lift">
          <hardwareInterface>hardware_interface/EffortJointInterface</hardwareInterface>
        </joint>
        <actuator name="ur10_shoulder_lift_motor">
          <hardwareInterface>hardware_interface/EffortJointInterface</hardwareInterface>
          <mechanicalReduction>1</mechanicalReduction>
        </actuator>
      </transmission>

      <transmission name="ur10_elbow_trans">
        <type>transmission_interface/SimpleTransmission</type>
        <joint name="ur10_elbow">
          <hardwareInterface>hardware_interface/EffortJointInterface</hardwareInterface>
        </joint>
        <actuator name="ur10_elbow_motor">
          <hardwareInterface>hardware_interface/EffortJointInterface</hardwareInterface>
          <mechanicalReduction>1</mechanicalReduction>
        </actuator>
      </transmission>

      <transmission name="ur10_wrist_1_trans">
        <type>transmission_interface/SimpleTransmission</type>
        <joint name="ur10_wrist_1">
          <hardwareInterface>hardware_interface/EffortJointInterface</hardwareInterface>
        </joint>
        <actuator name="ur10_wrist_1_motor">
          <hardwareInterface>hardware_interface/EffortJointInterface</hardwareInterface>
          <mechanicalReduction>1</mechanicalReduction>
        </actuator>
      </transmission>

      <transmission name="ur10_wrist_2_trans">
        <type>transmission_interface/SimpleTransmission</type>
        <joint name="ur10_wrist_2">
          <hardwareInterface>hardware_interface/EffortJointInterface</hardwareInterface>
        </joint>
        <actuator name="ur10_wrist_2_motor">
          <hardwareInterface>hardware_interface/EffortJointInterface</hardwareInterface>
          <mechanicalReduction>1</mechanicalReduction>
        </actuator>
      </transmission>

      <transmission name="ur10_wrist_3_trans">
        <type>transmission_interface/SimpleTransmission</type>
        <joint name="ur10_wrist_3">
          <hardwareInterface>hardware_interface/EffortJointInterface</hardwareInterface>
        </joint>
        <actuator name="ur10_wrist_3_motor">
          <hardwareInterface>hardware_interface/EffortJointInterface</hardwareInterface>
          <mechanicalReduction>1</mechanicalReduction>
        </actuator>
      </transmission>

      <gazebo>
        <plugin name="gazebo_ros_control" filename="libgazebo_ros_control.so">
          <robotNamespace>/assembly_gazebo</robotNamespace>
          <robotSimType>gazebo_ros_control/DefaultRobotHWSim</robotSimType>
        </plugin>
      </gazebo>

  </xacro:if>

  <xacro:if value="${ros_profile_arg == 'ros1' and ros_hardware_interface_arg == 'position'}">
      <transmission name="ur10_shoulder_pan_trans">
        <type>transmission_interface/SimpleTransmission</type>
        <joint name="ur10_shoulder_pan">
          <hardwareInterface>hardware_interface/PositionJointInterface</hardwareInterface>
        </joint>
        <actuator name="ur10_shoulder_pan_motor">
          <hardwareInterface>hardware_interface/PositionJointInterface</hardwareInterface>
          <mechanicalReduction>1</mechanicalReduction>
        </actuator>
      </transmission>

      <transmission name="ur10_shoulder_lift_trans">
        <type>transmission_interface/SimpleTransmission</type>
        <joint name="ur10_shoulder_lift">
          <hardwareInterface>hardware_interface/PositionJointInterface</hardwareInterface>
        </joint>
        <actuator name="ur10_shoulder_lift_motor">
          <hardwareInterface>hardware_interface/PositionJointInterface</hardwareInterface>
          <mechanicalReduction>1</mechanicalReduction>
        </actuator>
      </transmission>

      <transmission name="ur10_elbow_trans">
        <type>transmission_interface/SimpleTransmission</type>
        <joint name="ur10_elbow">
          <hardwareInterface>hardware_interface/PositionJointInterface</hardwareInterface>
        </joint>
        <actuator name="ur10_elbow_motor">
          <hardwareInterface>hardware_interface/PositionJointInterface</hardwareInterface>
          <mechanicalReduction>1</mechanicalReduction>
        </actuator>
      </transmission>

      <transmission name="ur10_wrist_1_trans">
        <type>transmission_interface/SimpleTransmission</type>
        <joint name="ur10_wrist_1">
          <hardwareInterface>hardware_interface/PositionJointInterface</hardwareInterface>
        </joint>
        <actuator name="ur10_wrist_1_motor">
          <hardwareInterface>hardware_interface/PositionJointInterface</hardwareInterface>
          <mechanicalReduction>1</mechanicalReduction>
        </actuator>
      </transmission>

      <transmission name="ur10_wrist_2_trans">
        <type>transmission_interface/SimpleTransmission</type>
        <joint name="ur10_wrist_2">
          <hardwareInterface>hardware_interface/PositionJointInterface</hardwareInterface>
        </joint>
        <actuator name="ur10_wrist_2_motor">
          <hardwareInterface>hardware_interface/PositionJointInterface</hardwareInterface>
          <mechanicalReduction>1</mechanicalReduction>
        </actuator>
      </transmission>

      <transmission name="ur10_wrist_3_trans">
        <type>transmission_interface/SimpleTransmission</type>
        <joint name="ur10_wrist_3">
          <hardwareInterface>hardware_interface/PositionJointInterface</hardwareInterface>
        </joint>
        <actuator name="ur10_wrist_3_motor">
          <hardwareInterface>hardware_interface/PositionJointInterface</hardwareInterface>
          <mechanicalReduction>1</mechanicalReduction>
        </actuator>
      </transmission>

      <gazebo>
        <plugin name="gazebo_ros_control" filename="libgazebo_ros_control.so">
          <robotNamespace>/assembly_gazebo</robotNamespace>
          <robotSimType>gazebo_ros_control/DefaultRobotHWSim</robotSimType>
        </plugin>
      </gazebo>

  </xacro:if>

  <xacro:if value="${ros_profile_arg == 'ros1' and ros_hardware_interface_arg == 'velocity'}">
      <transmission name="ur10_shoulder_pan_trans">
        <type>transmission_interface/SimpleTransmission</type>
        <joint name="ur10_shoulder_pan">
          <hardwareInterface>hardware_interface/VelocityJointInterface</hardwareInterface>
        </joint>
        <actuator name="ur10_shoulder_pan_motor">
          <hardwareInterface>hardware_interface/VelocityJointInterface</hardwareInterface>
          <mechanicalReduction>1</mechanicalReduction>
        </actuator>
      </transmission>

      <transmission name="ur10_shoulder_lift_trans">
        <type>transmission_interface/SimpleTransmission</type>
        <joint name="ur10_shoulder_lift">
          <hardwareInterface>hardware_interface/VelocityJointInterface</hardwareInterface>
        </joint>
        <actuator name="ur10_shoulder_lift_motor">
          <hardwareInterface>hardware_interface/VelocityJointInterface</hardwareInterface>
          <mechanicalReduction>1</mechanicalReduction>
        </actuator>
      </transmission>

      <transmission name="ur10_elbow_trans">
        <type>transmission_interface/SimpleTransmission</type>
        <joint name="ur10_elbow">
          <hardwareInterface>hardware_interface/VelocityJointInterface</hardwareInterface>
        </joint>
        <actuator name="ur10_elbow_motor">
          <hardwareInterface>hardware_interface/VelocityJointInterface</hardwareInterface>
          <mechanicalReduction>1</mechanicalReduction>
        </actuator>
      </transmission>

      <transmission name="ur10_wrist_1_trans">
        <type>transmission_interface/SimpleTransmission</type>
        <joint name="ur10_wrist_1">
          <hardwareInterface>hardware_interface/VelocityJointInterface</hardwareInterface>
        </joint>
        <actuator name="ur10_wrist_1_motor">
          <hardwareInterface>hardware_interface/VelocityJointInterface</hardwareInterface>
          <mechanicalReduction>1</mechanicalReduction>
        </actuator>
      </transmission>

      <transmission name="ur10_wrist_2_trans">
        <type>transmission_interface/SimpleTransmission</type>
        <joint name="ur10_wrist_2">
          <hardwareInterface>hardware_interface/VelocityJointInterface</hardwareInterface>
        </joint>
        <actuator name="ur10_wrist_2_motor">
          <hardwareInterface>hardware_interface/VelocityJointInterface</hardwareInterface>
          <mechanicalReduction>1</mechanicalReduction>
        </actuator>
      </transmission>

      <transmission name="ur10_wrist_3_trans">
        <type>transmission_interface/SimpleTransmission</type>
        <joint name="ur10_wrist_3">
          <hardwareInterface>hardware_interface/VelocityJointInterface</hardwareInterface>
        </joint>
        <actuator name="ur10_wrist_3_motor">
          <hardwareInterface>hardware_interface/VelocityJointInterface</hardwareInterface>
          <mechanicalReduction>1</mechanicalReduction>
        </actuator>
      </transmission>

      <gazebo>
        <plugin name="gazebo_ros_control" filename="libgazebo_ros_control.so">
          <robotNamespace>/assembly_gazebo</robotNamespace>
          <robotSimType>gazebo_ros_control/DefaultRobotHWSim</robotSimType>
        </plugin>
      </gazebo>

  </xacro:if>

  <xacro:if value="${ros_profile_arg == 'ros2' and ros_hardware_interface_arg == 'effort'}">
      <ros2_control name="assembly" type="system">
        <hardware>
          <xacro:if value="${hardware_backend_arg == 'gazebo'}">
            <plugin>gazebo_ros2_control/GazeboSystem</plugin>
          </xacro:if>
          <xacro:if value="${hardware_backend_arg == 'fake'}">
            <plugin>mock_components/GenericSystem</plugin>
            <param name="mock_sensor_commands">false</param>
            <param name="state_following_offset">0.0</param>
            <param name="calculate_dynamics">true</param>
          </xacro:if>
        </hardware>
        <joint name="ur10_shoulder_pan">
          <command_interface name="effort"/>
          <state_interface name="position">
            <param name="initial_value">2.0474984645843506</param>
          </state_interface>
          <state_interface name="velocity"/>
          <state_interface name="effort"/>
        </joint>
        <joint name="ur10_shoulder_lift">
          <command_interface name="effort"/>
          <state_interface name="position">
            <param name="initial_value">0.21928656101226807</param>
          </state_interface>
          <state_interface name="velocity"/>
          <state_interface name="effort"/>
        </joint>
        <joint name="ur10_elbow">
          <command_interface name="effort"/>
          <state_interface name="position">
            <param name="initial_value">-1.9548214117633265</param>
          </state_interface>
          <state_interface name="velocity"/>
          <state_interface name="effort"/>
        </joint>
        <joint name="ur10_wrist_1">
          <command_interface name="effort"/>
          <state_interface name="position">
            <param name="initial_value">-0.35923797289003545</param>
          </state_interface>
          <state_interface name="velocity"/>
          <state_interface name="effort"/>
        </joint>
        <joint name="ur10_wrist_2">
          <command_interface name="effort"/>
          <state_interface name="position">
            <param name="initial_value">2.0502676963806152</param>
          </state_interface>
          <state_interface name="velocity"/>
          <state_interface name="effort"/>
        </joint>
        <joint name="ur10_wrist_3">
          <command_interface name="effort"/>
          <state_interface name="position">
            <param name="initial_value">1.0330829620361328</param>
          </state_interface>
          <state_interface name="velocity"/>
          <state_interface name="effort"/>
        </joint>
      </ros2_control>

      <xacro:if value="${hardware_backend_arg == 'gazebo'}">
        <gazebo>
          <plugin name="gazebo_ros2_control" filename="libgazebo_ros2_control.so">
            <parameters>$(find assembly_description)/config/ros2_controllers.yaml</parameters>
            <robot_param>robot_description</robot_param>
            <robot_param_node>robot_state_publisher</robot_param_node>
          </plugin>
        </gazebo>
      </xacro:if>

  </xacro:if>

  <xacro:if value="${ros_profile_arg == 'ros2' and ros_hardware_interface_arg == 'position'}">
      <ros2_control name="assembly" type="system">
        <hardware>
          <xacro:if value="${hardware_backend_arg == 'gazebo'}">
            <plugin>gazebo_ros2_control/GazeboSystem</plugin>
          </xacro:if>
          <xacro:if value="${hardware_backend_arg == 'fake'}">
            <plugin>mock_components/GenericSystem</plugin>
            <param name="mock_sensor_commands">false</param>
            <param name="state_following_offset">0.0</param>
            <param name="calculate_dynamics">true</param>
          </xacro:if>
        </hardware>
        <joint name="ur10_shoulder_pan">
          <command_interface name="position"/>
          <state_interface name="position">
            <param name="initial_value">2.0474984645843506</param>
          </state_interface>
          <state_interface name="velocity"/>
        </joint>
        <joint name="ur10_shoulder_lift">
          <command_interface name="position"/>
          <state_interface name="position">
            <param name="initial_value">0.21928656101226807</param>
          </state_interface>
          <state_interface name="velocity"/>
        </joint>
        <joint name="ur10_elbow">
          <command_interface name="position"/>
          <state_interface name="position">
            <param name="initial_value">-1.9548214117633265</param>
          </state_interface>
          <state_interface name="velocity"/>
        </joint>
        <joint name="ur10_wrist_1">
          <command_interface name="position"/>
          <state_interface name="position">
            <param name="initial_value">-0.35923797289003545</param>
          </state_interface>
          <state_interface name="velocity"/>
        </joint>
        <joint name="ur10_wrist_2">
          <command_interface name="position"/>
          <state_interface name="position">
            <param name="initial_value">2.0502676963806152</param>
          </state_interface>
          <state_interface name="velocity"/>
        </joint>
        <joint name="ur10_wrist_3">
          <command_interface name="position"/>
          <state_interface name="position">
            <param name="initial_value">1.0330829620361328</param>
          </state_interface>
          <state_interface name="velocity"/>
        </joint>
      </ros2_control>

      <xacro:if value="${hardware_backend_arg == 'gazebo'}">
        <gazebo>
          <plugin name="gazebo_ros2_control" filename="libgazebo_ros2_control.so">
            <parameters>$(find assembly_description)/config/ros2_controllers.yaml</parameters>
            <robot_param>robot_description</robot_param>
            <robot_param_node>robot_state_publisher</robot_param_node>
          </plugin>
        </gazebo>
      </xacro:if>

  </xacro:if>

  <xacro:if value="${ros_profile_arg == 'ros2' and ros_hardware_interface_arg == 'velocity'}">
      <ros2_control name="assembly" type="system">
        <hardware>
          <xacro:if value="${hardware_backend_arg == 'gazebo'}">
            <plugin>gazebo_ros2_control/GazeboSystem</plugin>
          </xacro:if>
          <xacro:if value="${hardware_backend_arg == 'fake'}">
            <plugin>mock_components/GenericSystem</plugin>
            <param name="mock_sensor_commands">false</param>
            <param name="state_following_offset">0.0</param>
            <param name="calculate_dynamics">true</param>
          </xacro:if>
        </hardware>
        <joint name="ur10_shoulder_pan">
          <command_interface name="velocity"/>
          <state_interface name="position">
            <param name="initial_value">2.0474984645843506</param>
          </state_interface>
          <state_interface name="velocity"/>
        </joint>
        <joint name="ur10_shoulder_lift">
          <command_interface name="velocity"/>
          <state_interface name="position">
            <param name="initial_value">0.21928656101226807</param>
          </state_interface>
          <state_interface name="velocity"/>
        </joint>
        <joint name="ur10_elbow">
          <command_interface name="velocity"/>
          <state_interface name="position">
            <param name="initial_value">-1.9548214117633265</param>
          </state_interface>
          <state_interface name="velocity"/>
        </joint>
        <joint name="ur10_wrist_1">
          <command_interface name="velocity"/>
          <state_interface name="position">
            <param name="initial_value">-0.35923797289003545</param>
          </state_interface>
          <state_interface name="velocity"/>
        </joint>
        <joint name="ur10_wrist_2">
          <command_interface name="velocity"/>
          <state_interface name="position">
            <param name="initial_value">2.0502676963806152</param>
          </state_interface>
          <state_interface name="velocity"/>
        </joint>
        <joint name="ur10_wrist_3">
          <command_interface name="velocity"/>
          <state_interface name="position">
            <param name="initial_value">1.0330829620361328</param>
          </state_interface>
          <state_interface name="velocity"/>
        </joint>
      </ros2_control>

      <xacro:if value="${hardware_backend_arg == 'gazebo'}">
        <gazebo>
          <plugin name="gazebo_ros2_control" filename="libgazebo_ros2_control.so">
            <parameters>$(find assembly_description)/config/ros2_controllers.yaml</parameters>
            <robot_param>robot_description</robot_param>
            <robot_param_node>robot_state_publisher</robot_param_node>
          </plugin>
        </gazebo>
      </xacro:if>

  </xacro:if>
</robot>
